/root/workhosesystem/
2018-10-12 14:54:40,579 - ERROR - systemlog.py - log_error - 47 - could not convert string to float: 
2018-10-12 15:12:28,388 - ERROR - systemlog.py - log_error - 47 - could not convert string to float: '两句'
2018-10-18 08:57:08,653 - ERROR - systemlog.py - log_error - 47 - could not convert string to float: 
2018-10-19 17:04:39,115 - ERROR - systemlog.py - log_error - 47 - could not convert string to float: 
2018-10-23 11:07:54,625 - ERROR - systemlog.py - log_error - 47 - foreign key constraint failed
D:\code\PycharmProjects\WorkHourSystem\
D:\code\PycharmProjects\WorkHourSystem\
D:\code\PycharmProjects\WorkHourSystem\
2018-10-25 09:53:44,407 - ERROR - systemlog.py - log_error - 47 - near "where": syntax error
2018-10-25 09:53:45,374 - ERROR - systemlog.py - log_error - 47 - near "where": syntax error
2018-10-25 09:53:57,144 - ERROR - systemlog.py - log_error - 47 - near "where": syntax error
2018-10-25 09:53:57,355 - ERROR - systemlog.py - log_error - 47 - near "where": syntax error
2018-10-25 09:53:57,542 - ERROR - systemlog.py - log_error - 47 - near "where": syntax error
2018-10-25 09:53:57,904 - ERROR - systemlog.py - log_error - 47 - near "where": syntax error
2018-10-25 09:53:58,284 - ERROR - systemlog.py - log_error - 47 - near "where": syntax error
2018-10-25 09:53:58,475 - ERROR - systemlog.py - log_error - 47 - near "where": syntax error
2018-10-25 09:53:58,659 - ERROR - systemlog.py - log_error - 47 - near "where": syntax error
2018-10-25 09:53:59,636 - ERROR - systemlog.py - log_error - 47 - near "where": syntax error
D:\code\PycharmProjects\WorkHourSystem\
D:\code\PycharmProjects\WorkHourSystem\
D:\code\PycharmProjects\WorkHourSystem\
D:\code\PycharmProjects\WorkHourSystem\
D:\code\PycharmProjects\WorkHourSystem\
D:\code\PycharmProjects\WorkHourSystem\
D:\code\PycharmProjects\WorkHourSystem\
D:\code\PycharmProjects\WorkHourSystem\
D:\code\PycharmProjects\WorkHourSystem\
D:\code\PycharmProjects\WorkHourSystem\
D:\code\PycharmProjects\WorkHourSystem\
D:\code\PycharmProjects\WorkHourSystem\
D:\code\PycharmProjects\WorkHourSystem\
D:\code\PycharmProjects\WorkHourSystem\
D:\code\PycharmProjects\WorkHourSystem\
D:\code\PycharmProjects\WorkHourSystem\
2018-10-25 10:44:48,430 - ERROR - systemlog.py - log_error - 47 - no such column: project_id
2018-10-25 10:44:51,536 - ERROR - systemlog.py - log_error - 47 - no such column: project_id
D:\code\PycharmProjects\WorkHourSystem\
D:\code\PycharmProjects\WorkHourSystem\
D:\code\PycharmProjects\WorkHourSystem\
D:\code\PycharmProjects\WorkHourSystem\
D:\code\PycharmProjects\WorkHourSystem\
D:\code\PycharmProjects\WorkHourSystem\
D:\code\PycharmProjects\WorkHourSystem\
D:\code\PycharmProjects\WorkHourSystem\
D:\code\PycharmProjects\WorkHourSystem\
D:\code\PycharmProjects\WorkHourSystem\
/Users/jiangtao/PycharmProjects/WorkHourSystem/
2018-10-25 15:55:25,443 - ERROR - systemlog.py - log_error - 47 - 'NoneType' object has no attribute 'execute_query'
2018-10-25 15:55:25,444 - ERROR - systemlog.py - log_error - 47 - 'NoneType' object has no attribute 'execute_query'
2018-10-25 15:55:28,892 - ERROR - systemlog.py - log_error - 47 - 'NoneType' object has no attribute 'execute_query'
2018-10-25 15:55:30,701 - ERROR - systemlog.py - log_error - 47 - 'NoneType' object has no attribute 'execute_query'
2018-10-25 15:55:30,702 - ERROR - systemlog.py - log_error - 47 - 'NoneType' object has no attribute 'execute_query'
2018-10-25 15:55:30,702 - ERROR - systemlog.py - log_error - 47 - 'NoneType' object has no attribute 'execute_query'
2018-10-25 15:55:38,498 - ERROR - systemlog.py - log_error - 47 - 'NoneType' object has no attribute 'execute_query'
2018-10-25 15:55:42,955 - ERROR - systemlog.py - log_error - 47 - 'NoneType' object has no attribute 'execute_query_single'
2018-10-25 16:01:44,710 - ERROR - systemlog.py - log_error - 47 - 'NoneType' object has no attribute 'execute_query_single'
2018-10-25 16:01:49,742 - ERROR - systemlog.py - log_error - 47 - 'NoneType' object has no attribute 'execute_query_single'
2018-10-25 16:09:19,187 - ERROR - systemlog.py - log_error - 47 - 'NoneType' object has no attribute 'execute_query_single'
2018-10-25 16:12:12,094 - ERROR - systemlog.py - log_error - 47 - 'NoneType' object has no attribute 'execute_query'
2018-10-25 16:12:39,153 - ERROR - systemlog.py - log_error - 47 - 'NoneType' object has no attribute 'execute_query'
2018-10-25 16:12:59,038 - ERROR - systemlog.py - log_error - 47 - 'NoneType' object has no attribute 'execute_query'
2018-10-25 16:13:08,611 - ERROR - systemlog.py - log_error - 47 - 'NoneType' object has no attribute 'execute_query'
2018-10-25 16:13:43,728 - ERROR - systemlog.py - log_error - 47 - 'NoneType' object has no attribute 'execute_query'
2018-10-25 16:13:48,441 - ERROR - systemlog.py - log_error - 47 - 'NoneType' object has no attribute 'execute_query'
2018-10-25 16:14:10,741 - ERROR - systemlog.py - log_error - 47 - 'NoneType' object has no attribute 'execute_query'
2018-10-25 16:14:17,070 - ERROR - systemlog.py - log_error - 47 - 'NoneType' object has no attribute 'execute_query'
2018-10-25 16:14:45,827 - ERROR - systemlog.py - log_error - 47 - 'NoneType' object has no attribute 'execute_query'
2018-10-25 16:19:26,724 - ERROR - systemlog.py - log_error - 47 - 'NoneType' object has no attribute 'execute_query'
2018-10-25 16:22:09,952 - ERROR - systemlog.py - log_error - 47 - 'object' object has no attribute 'execute_query'
2018-10-25 16:22:46,308 - ERROR - systemlog.py - log_error - 47 - 'str' object has no attribute 'execute_query'
2018-10-25 16:23:57,270 - ERROR - systemlog.py - log_error - 47 - 'NoneType' object has no attribute 'execute_query'
2018-10-25 16:25:11,797 - ERROR - systemlog.py - log_error - 47 - 'NoneType' object has no attribute 'execute_query'
2018-10-25 16:26:10,825 - ERROR - systemlog.py - log_error - 47 - name 'dbpool_util' is not defined
2018-10-25 16:26:32,841 - ERROR - systemlog.py - log_error - 47 - name 'dbpool_util' is not defined
2018-10-25 16:27:44,280 - ERROR - systemlog.py - log_error - 47 - name 'dbpool_util' is not defined
2018-10-25 16:28:27,904 - ERROR - systemlog.py - log_error - 47 - name 'WORK_PATH' is not defined
2018-10-25 16:29:31,751 - ERROR - systemlog.py - log_error - 47 - 'NoneType' object has no attribute 'execute_query_single'
2018-10-25 16:41:20,476 - ERROR - systemlog.py - log_error - 47 - invalid literal for int() with base 10: '请先选择部门'
2018-10-25 16:45:41,126 - ERROR - systemlog.py - log_error - 47 - FOREIGN KEY constraint failed
2018-10-25 17:06:44,415 - ERROR - systemlog.py - log_error - 47 - SQLite objects created in a thread can only be used in that same thread.The object was created in thread id 123145373679616 and this is thread id 123145378934784
2018-10-25 17:07:04,714 - ERROR - systemlog.py - log_error - 47 - SQLite objects created in a thread can only be used in that same thread.The object was created in thread id 123145373679616 and this is thread id 123145378934784
2018-10-25 17:07:04,715 - ERROR - systemlog.py - log_error - 47 - SQLite objects created in a thread can only be used in that same thread.The object was created in thread id 123145373679616 and this is thread id 123145378934784
2018-10-25 17:07:09,217 - ERROR - systemlog.py - log_error - 47 - SQLite objects created in a thread can only be used in that same thread.The object was created in thread id 123145373679616 and this is thread id 123145378934784
2018-10-25 17:07:09,218 - ERROR - systemlog.py - log_error - 47 - SQLite objects created in a thread can only be used in that same thread.The object was created in thread id 123145373679616 and this is thread id 123145378934784
2018-10-25 17:07:14,284 - ERROR - systemlog.py - log_error - 47 - SQLite objects created in a thread can only be used in that same thread.The object was created in thread id 123145373679616 and this is thread id 123145378934784
2018-10-25 17:07:14,284 - ERROR - systemlog.py - log_error - 47 - SQLite objects created in a thread can only be used in that same thread.The object was created in thread id 123145373679616 and this is thread id 123145378934784
2018-10-25 17:07:40,698 - ERROR - systemlog.py - log_error - 47 - SQLite objects created in a thread can only be used in that same thread.The object was created in thread id 123145373679616 and this is thread id 123145378934784
2018-10-25 17:07:40,699 - ERROR - systemlog.py - log_error - 47 - SQLite objects created in a thread can only be used in that same thread.The object was created in thread id 123145373679616 and this is thread id 123145378934784
2018-10-25 17:09:03,423 - ERROR - systemlog.py - log_error - 47 - SQLite objects created in a thread can only be used in that same thread.The object was created in thread id 123145353576448 and this is thread id 123145358831616
2018-10-25 17:09:03,424 - ERROR - systemlog.py - log_error - 47 - SQLite objects created in a thread can only be used in that same thread.The object was created in thread id 123145353576448 and this is thread id 123145358831616
2018-10-25 17:09:03,424 - ERROR - systemlog.py - log_error - 47 - SQLite objects created in a thread can only be used in that same thread.The object was created in thread id 123145353576448 and this is thread id 123145358831616
2018-10-25 17:09:03,425 - ERROR - systemlog.py - log_error - 47 - SQLite objects created in a thread can only be used in that same thread.The object was created in thread id 123145353576448 and this is thread id 123145358831616
2018-10-25 17:09:04,077 - ERROR - systemlog.py - log_error - 47 - SQLite objects created in a thread can only be used in that same thread.The object was created in thread id 123145353576448 and this is thread id 123145358831616
2018-10-25 17:09:04,077 - ERROR - systemlog.py - log_error - 47 - SQLite objects created in a thread can only be used in that same thread.The object was created in thread id 123145353576448 and this is thread id 123145358831616
2018-10-25 17:09:04,077 - ERROR - systemlog.py - log_error - 47 - SQLite objects created in a thread can only be used in that same thread.The object was created in thread id 123145353576448 and this is thread id 123145358831616
2018-10-25 17:09:04,078 - ERROR - systemlog.py - log_error - 47 - SQLite objects created in a thread can only be used in that same thread.The object was created in thread id 123145353576448 and this is thread id 123145358831616
2018-10-25 17:09:04,443 - ERROR - systemlog.py - log_error - 47 - SQLite objects created in a thread can only be used in that same thread.The object was created in thread id 123145353576448 and this is thread id 123145358831616
2018-10-25 17:09:04,444 - ERROR - systemlog.py - log_error - 47 - SQLite objects created in a thread can only be used in that same thread.The object was created in thread id 123145353576448 and this is thread id 123145358831616
2018-10-25 17:09:04,444 - ERROR - systemlog.py - log_error - 47 - SQLite objects created in a thread can only be used in that same thread.The object was created in thread id 123145353576448 and this is thread id 123145358831616
2018-10-25 17:09:04,444 - ERROR - systemlog.py - log_error - 47 - SQLite objects created in a thread can only be used in that same thread.The object was created in thread id 123145353576448 and this is thread id 123145358831616
2018-10-25 17:09:07,474 - ERROR - systemlog.py - log_error - 47 - SQLite objects created in a thread can only be used in that same thread.The object was created in thread id 123145353576448 and this is thread id 123145358831616
2018-10-25 17:09:08,972 - ERROR - systemlog.py - log_error - 47 - SQLite objects created in a thread can only be used in that same thread.The object was created in thread id 123145353576448 and this is thread id 123145358831616
2018-10-25 17:09:08,973 - ERROR - systemlog.py - log_error - 47 - SQLite objects created in a thread can only be used in that same thread.The object was created in thread id 123145353576448 and this is thread id 123145358831616
2018-10-25 17:09:08,973 - ERROR - systemlog.py - log_error - 47 - SQLite objects created in a thread can only be used in that same thread.The object was created in thread id 123145353576448 and this is thread id 123145358831616
2018-10-25 17:09:08,973 - ERROR - systemlog.py - log_error - 47 - SQLite objects created in a thread can only be used in that same thread.The object was created in thread id 123145353576448 and this is thread id 123145358831616
2018-10-25 17:09:10,758 - ERROR - systemlog.py - log_error - 47 - SQLite objects created in a thread can only be used in that same thread.The object was created in thread id 123145353576448 and this is thread id 123145358831616
2018-10-25 17:09:10,758 - ERROR - systemlog.py - log_error - 47 - SQLite objects created in a thread can only be used in that same thread.The object was created in thread id 123145353576448 and this is thread id 123145358831616
2018-10-25 17:09:10,759 - ERROR - systemlog.py - log_error - 47 - SQLite objects created in a thread can only be used in that same thread.The object was created in thread id 123145353576448 and this is thread id 123145358831616
2018-10-25 17:09:10,759 - ERROR - systemlog.py - log_error - 47 - SQLite objects created in a thread can only be used in that same thread.The object was created in thread id 123145353576448 and this is thread id 123145358831616
2018-10-25 17:09:11,376 - ERROR - systemlog.py - log_error - 47 - SQLite objects created in a thread can only be used in that same thread.The object was created in thread id 123145353576448 and this is thread id 123145358831616
2018-10-25 17:09:11,376 - ERROR - systemlog.py - log_error - 47 - SQLite objects created in a thread can only be used in that same thread.The object was created in thread id 123145353576448 and this is thread id 123145358831616
2018-10-25 17:09:11,377 - ERROR - systemlog.py - log_error - 47 - SQLite objects created in a thread can only be used in that same thread.The object was created in thread id 123145353576448 and this is thread id 123145358831616
2018-10-25 17:09:11,377 - ERROR - systemlog.py - log_error - 47 - SQLite objects created in a thread can only be used in that same thread.The object was created in thread id 123145353576448 and this is thread id 123145358831616
2018-10-25 17:09:11,744 - ERROR - systemlog.py - log_error - 47 - SQLite objects created in a thread can only be used in that same thread.The object was created in thread id 123145353576448 and this is thread id 123145358831616
2018-10-25 17:09:11,745 - ERROR - systemlog.py - log_error - 47 - SQLite objects created in a thread can only be used in that same thread.The object was created in thread id 123145353576448 and this is thread id 123145358831616
2018-10-25 17:09:11,745 - ERROR - systemlog.py - log_error - 47 - SQLite objects created in a thread can only be used in that same thread.The object was created in thread id 123145353576448 and this is thread id 123145358831616
2018-10-25 17:09:11,745 - ERROR - systemlog.py - log_error - 47 - SQLite objects created in a thread can only be used in that same thread.The object was created in thread id 123145353576448 and this is thread id 123145358831616
2018-10-25 17:09:12,116 - ERROR - systemlog.py - log_error - 47 - SQLite objects created in a thread can only be used in that same thread.The object was created in thread id 123145353576448 and this is thread id 123145358831616
2018-10-25 17:09:12,116 - ERROR - systemlog.py - log_error - 47 - SQLite objects created in a thread can only be used in that same thread.The object was created in thread id 123145353576448 and this is thread id 123145358831616
2018-10-25 17:09:12,116 - ERROR - systemlog.py - log_error - 47 - SQLite objects created in a thread can only be used in that same thread.The object was created in thread id 123145353576448 and this is thread id 123145358831616
2018-10-25 17:09:12,117 - ERROR - systemlog.py - log_error - 47 - SQLite objects created in a thread can only be used in that same thread.The object was created in thread id 123145353576448 and this is thread id 123145358831616
2018-10-25 17:09:12,510 - ERROR - systemlog.py - log_error - 47 - SQLite objects created in a thread can only be used in that same thread.The object was created in thread id 123145353576448 and this is thread id 123145358831616
2018-10-25 17:09:12,510 - ERROR - systemlog.py - log_error - 47 - SQLite objects created in a thread can only be used in that same thread.The object was created in thread id 123145353576448 and this is thread id 123145358831616
2018-10-25 17:09:12,511 - ERROR - systemlog.py - log_error - 47 - SQLite objects created in a thread can only be used in that same thread.The object was created in thread id 123145353576448 and this is thread id 123145358831616
2018-10-25 17:09:12,511 - ERROR - systemlog.py - log_error - 47 - SQLite objects created in a thread can only be used in that same thread.The object was created in thread id 123145353576448 and this is thread id 123145358831616
2018-10-25 17:09:12,888 - ERROR - systemlog.py - log_error - 47 - SQLite objects created in a thread can only be used in that same thread.The object was created in thread id 123145353576448 and this is thread id 123145358831616
2018-10-25 17:09:12,889 - ERROR - systemlog.py - log_error - 47 - SQLite objects created in a thread can only be used in that same thread.The object was created in thread id 123145353576448 and this is thread id 123145358831616
2018-10-25 17:09:12,889 - ERROR - systemlog.py - log_error - 47 - SQLite objects created in a thread can only be used in that same thread.The object was created in thread id 123145353576448 and this is thread id 123145358831616
2018-10-25 17:09:12,889 - ERROR - systemlog.py - log_error - 47 - SQLite objects created in a thread can only be used in that same thread.The object was created in thread id 123145353576448 and this is thread id 123145358831616
2018-10-25 17:09:13,753 - ERROR - systemlog.py - log_error - 47 - SQLite objects created in a thread can only be used in that same thread.The object was created in thread id 123145353576448 and this is thread id 123145358831616
2018-10-25 17:09:13,753 - ERROR - systemlog.py - log_error - 47 - SQLite objects created in a thread can only be used in that same thread.The object was created in thread id 123145353576448 and this is thread id 123145358831616
2018-10-25 17:09:13,754 - ERROR - systemlog.py - log_error - 47 - SQLite objects created in a thread can only be used in that same thread.The object was created in thread id 123145353576448 and this is thread id 123145358831616
2018-10-25 17:09:13,754 - ERROR - systemlog.py - log_error - 47 - SQLite objects created in a thread can only be used in that same thread.The object was created in thread id 123145353576448 and this is thread id 123145358831616
2018-10-25 17:09:14,140 - ERROR - systemlog.py - log_error - 47 - SQLite objects created in a thread can only be used in that same thread.The object was created in thread id 123145353576448 and this is thread id 123145358831616
2018-10-25 17:09:14,140 - ERROR - systemlog.py - log_error - 47 - SQLite objects created in a thread can only be used in that same thread.The object was created in thread id 123145353576448 and this is thread id 123145358831616
2018-10-25 17:09:14,140 - ERROR - systemlog.py - log_error - 47 - SQLite objects created in a thread can only be used in that same thread.The object was created in thread id 123145353576448 and this is thread id 123145358831616
2018-10-25 17:09:14,141 - ERROR - systemlog.py - log_error - 47 - SQLite objects created in a thread can only be used in that same thread.The object was created in thread id 123145353576448 and this is thread id 123145358831616
2018-10-25 17:09:14,490 - ERROR - systemlog.py - log_error - 47 - SQLite objects created in a thread can only be used in that same thread.The object was created in thread id 123145353576448 and this is thread id 123145358831616
2018-10-25 17:09:14,490 - ERROR - systemlog.py - log_error - 47 - SQLite objects created in a thread can only be used in that same thread.The object was created in thread id 123145353576448 and this is thread id 123145358831616
2018-10-25 17:09:14,490 - ERROR - systemlog.py - log_error - 47 - SQLite objects created in a thread can only be used in that same thread.The object was created in thread id 123145353576448 and this is thread id 123145358831616
2018-10-25 17:09:14,491 - ERROR - systemlog.py - log_error - 47 - SQLite objects created in a thread can only be used in that same thread.The object was created in thread id 123145353576448 and this is thread id 123145358831616
2018-10-25 17:09:15,430 - ERROR - systemlog.py - log_error - 47 - SQLite objects created in a thread can only be used in that same thread.The object was created in thread id 123145353576448 and this is thread id 123145358831616
2018-10-25 17:09:15,430 - ERROR - systemlog.py - log_error - 47 - SQLite objects created in a thread can only be used in that same thread.The object was created in thread id 123145353576448 and this is thread id 123145358831616
2018-10-25 17:09:18,587 - ERROR - systemlog.py - log_error - 47 - SQLite objects created in a thread can only be used in that same thread.The object was created in thread id 123145353576448 and this is thread id 123145358831616
2018-10-25 17:09:19,030 - ERROR - systemlog.py - log_error - 47 - SQLite objects created in a thread can only be used in that same thread.The object was created in thread id 123145353576448 and this is thread id 123145358831616
2018-10-25 17:09:20,034 - ERROR - systemlog.py - log_error - 47 - SQLite objects created in a thread can only be used in that same thread.The object was created in thread id 123145353576448 and this is thread id 123145358831616
2018-10-25 17:09:20,035 - ERROR - systemlog.py - log_error - 47 - SQLite objects created in a thread can only be used in that same thread.The object was created in thread id 123145353576448 and this is thread id 123145358831616
2018-10-25 17:09:20,035 - ERROR - systemlog.py - log_error - 47 - SQLite objects created in a thread can only be used in that same thread.The object was created in thread id 123145353576448 and this is thread id 123145358831616
2018-10-25 17:09:20,035 - ERROR - systemlog.py - log_error - 47 - SQLite objects created in a thread can only be used in that same thread.The object was created in thread id 123145353576448 and this is thread id 123145358831616
2018-10-25 17:09:20,905 - ERROR - systemlog.py - log_error - 47 - SQLite objects created in a thread can only be used in that same thread.The object was created in thread id 123145353576448 and this is thread id 123145358831616
2018-10-25 17:09:20,905 - ERROR - systemlog.py - log_error - 47 - SQLite objects created in a thread can only be used in that same thread.The object was created in thread id 123145353576448 and this is thread id 123145358831616
2018-10-25 17:09:20,906 - ERROR - systemlog.py - log_error - 47 - SQLite objects created in a thread can only be used in that same thread.The object was created in thread id 123145353576448 and this is thread id 123145358831616
2018-10-25 17:09:20,906 - ERROR - systemlog.py - log_error - 47 - SQLite objects created in a thread can only be used in that same thread.The object was created in thread id 123145353576448 and this is thread id 123145358831616
2018-10-25 17:09:21,407 - ERROR - systemlog.py - log_error - 47 - SQLite objects created in a thread can only be used in that same thread.The object was created in thread id 123145353576448 and this is thread id 123145358831616
2018-10-25 17:09:21,408 - ERROR - systemlog.py - log_error - 47 - SQLite objects created in a thread can only be used in that same thread.The object was created in thread id 123145353576448 and this is thread id 123145358831616
2018-10-25 17:09:21,408 - ERROR - systemlog.py - log_error - 47 - SQLite objects created in a thread can only be used in that same thread.The object was created in thread id 123145353576448 and this is thread id 123145358831616
2018-10-25 17:09:21,408 - ERROR - systemlog.py - log_error - 47 - SQLite objects created in a thread can only be used in that same thread.The object was created in thread id 123145353576448 and this is thread id 123145358831616
2018-10-25 17:09:22,197 - ERROR - systemlog.py - log_error - 47 - SQLite objects created in a thread can only be used in that same thread.The object was created in thread id 123145353576448 and this is thread id 123145358831616
2018-10-25 17:09:22,198 - ERROR - systemlog.py - log_error - 47 - SQLite objects created in a thread can only be used in that same thread.The object was created in thread id 123145353576448 and this is thread id 123145358831616
2018-10-25 17:09:22,198 - ERROR - systemlog.py - log_error - 47 - SQLite objects created in a thread can only be used in that same thread.The object was created in thread id 123145353576448 and this is thread id 123145358831616
2018-10-25 17:09:22,198 - ERROR - systemlog.py - log_error - 47 - SQLite objects created in a thread can only be used in that same thread.The object was created in thread id 123145353576448 and this is thread id 123145358831616
2018-10-25 17:09:22,628 - ERROR - systemlog.py - log_error - 47 - SQLite objects created in a thread can only be used in that same thread.The object was created in thread id 123145353576448 and this is thread id 123145358831616
2018-10-25 17:09:22,629 - ERROR - systemlog.py - log_error - 47 - SQLite objects created in a thread can only be used in that same thread.The object was created in thread id 123145353576448 and this is thread id 123145358831616
2018-10-25 17:09:22,629 - ERROR - systemlog.py - log_error - 47 - SQLite objects created in a thread can only be used in that same thread.The object was created in thread id 123145353576448 and this is thread id 123145358831616
2018-10-25 17:09:22,629 - ERROR - systemlog.py - log_error - 47 - SQLite objects created in a thread can only be used in that same thread.The object was created in thread id 123145353576448 and this is thread id 123145358831616
2018-10-25 17:09:23,025 - ERROR - systemlog.py - log_error - 47 - SQLite objects created in a thread can only be used in that same thread.The object was created in thread id 123145353576448 and this is thread id 123145358831616
2018-10-25 17:09:23,026 - ERROR - systemlog.py - log_error - 47 - SQLite objects created in a thread can only be used in that same thread.The object was created in thread id 123145353576448 and this is thread id 123145358831616
2018-10-25 17:09:23,026 - ERROR - systemlog.py - log_error - 47 - SQLite objects created in a thread can only be used in that same thread.The object was created in thread id 123145353576448 and this is thread id 123145358831616
2018-10-25 17:09:23,026 - ERROR - systemlog.py - log_error - 47 - SQLite objects created in a thread can only be used in that same thread.The object was created in thread id 123145353576448 and this is thread id 123145358831616
2018-10-25 17:09:23,589 - ERROR - systemlog.py - log_error - 47 - SQLite objects created in a thread can only be used in that same thread.The object was created in thread id 123145353576448 and this is thread id 123145358831616
2018-10-25 17:09:23,590 - ERROR - systemlog.py - log_error - 47 - SQLite objects created in a thread can only be used in that same thread.The object was created in thread id 123145353576448 and this is thread id 123145358831616
2018-10-25 17:09:23,590 - ERROR - systemlog.py - log_error - 47 - SQLite objects created in a thread can only be used in that same thread.The object was created in thread id 123145353576448 and this is thread id 123145358831616
2018-10-25 17:09:23,590 - ERROR - systemlog.py - log_error - 47 - SQLite objects created in a thread can only be used in that same thread.The object was created in thread id 123145353576448 and this is thread id 123145358831616
2018-10-25 17:09:24,727 - ERROR - systemlog.py - log_error - 47 - SQLite objects created in a thread can only be used in that same thread.The object was created in thread id 123145353576448 and this is thread id 123145358831616
2018-10-25 17:09:24,728 - ERROR - systemlog.py - log_error - 47 - SQLite objects created in a thread can only be used in that same thread.The object was created in thread id 123145353576448 and this is thread id 123145358831616
2018-10-25 17:09:24,728 - ERROR - systemlog.py - log_error - 47 - SQLite objects created in a thread can only be used in that same thread.The object was created in thread id 123145353576448 and this is thread id 123145358831616
2018-10-25 17:09:24,729 - ERROR - systemlog.py - log_error - 47 - SQLite objects created in a thread can only be used in that same thread.The object was created in thread id 123145353576448 and this is thread id 123145358831616
2018-10-26 11:18:46,961 - ERROR - systemlog.py - log_error - 47 - UNIQUE constraint failed: t_user.user
2018-10-26 11:18:52,936 - ERROR - systemlog.py - log_error - 47 - UNIQUE constraint failed: t_user.user
2018-10-26 11:20:29,570 - ERROR - systemlog.py - log_error - 47 - UNIQUE constraint failed: t_user.user
2018-11-02 10:49:33,064 - ERROR - systemlog.py - log_error - 47 - UNIQUE constraint failed: t_project_user.user_id, t_project_user.project_id
2018-11-02 11:00:33,124 - ERROR - systemlog.py - log_error - 47 - UNIQUE constraint failed: t_project_user.user_id, t_project_user.project_id
2018-11-02 17:51:43,607 - ERROR - systemlog.py - log_error - 47 - UNIQUE constraint failed: t_project_user.user_id, t_project_user.project_id
2018-11-13 15:44:38,482 - ERROR - systemlog.py - log_error - 47 - Incorrect number of bindings supplied. The current statement uses 2, and there are 1 supplied.
2018-11-13 15:44:39,262 - ERROR - systemlog.py - log_error - 47 - Incorrect number of bindings supplied. The current statement uses 2, and there are 1 supplied.
2018-11-13 15:44:39,719 - ERROR - systemlog.py - log_error - 47 - Incorrect number of bindings supplied. The current statement uses 2, and there are 1 supplied.
2018-11-13 15:44:40,923 - ERROR - systemlog.py - log_error - 47 - Incorrect number of bindings supplied. The current statement uses 2, and there are 1 supplied.
2018-11-13 16:26:03,554 - ERROR - systemlog.py - log_error - 47 - Incorrect number of bindings supplied. The current statement uses 2, and there are 1 supplied.
2018-11-13 16:26:58,565 - ERROR - systemlog.py - log_error - 47 - Incorrect number of bindings supplied. The current statement uses 2, and there are 1 supplied.
2018-11-13 16:27:37,463 - ERROR - systemlog.py - log_error - 47 - Incorrect number of bindings supplied. The current statement uses 2, and there are 1 supplied.
2018-11-13 16:29:04,538 - ERROR - systemlog.py - log_error - 47 - Incorrect number of bindings supplied. The current statement uses 2, and there are 1 supplied.
2018-11-13 16:30:02,708 - ERROR - systemlog.py - log_error - 47 - Incorrect number of bindings supplied. The current statement uses 2, and there are 1 supplied.
2018-11-13 16:30:03,426 - ERROR - systemlog.py - log_error - 47 - Incorrect number of bindings supplied. The current statement uses 2, and there are 1 supplied.
2018-11-13 16:30:03,600 - ERROR - systemlog.py - log_error - 47 - Incorrect number of bindings supplied. The current statement uses 2, and there are 1 supplied.
2018-11-13 16:30:10,332 - ERROR - systemlog.py - log_error - 47 - Incorrect number of bindings supplied. The current statement uses 2, and there are 1 supplied.
2018-11-13 16:30:13,090 - ERROR - systemlog.py - log_error - 47 - Incorrect number of bindings supplied. The current statement uses 2, and there are 1 supplied.
2018-11-13 16:30:15,986 - ERROR - systemlog.py - log_error - 47 - Incorrect number of bindings supplied. The current statement uses 2, and there are 1 supplied.
2018-11-13 16:30:18,979 - ERROR - systemlog.py - log_error - 47 - Incorrect number of bindings supplied. The current statement uses 2, and there are 1 supplied.
2018-11-13 16:30:26,994 - ERROR - systemlog.py - log_error - 47 - Incorrect number of bindings supplied. The current statement uses 2, and there are 1 supplied.
2018-11-13 16:30:40,367 - ERROR - systemlog.py - log_error - 47 - Incorrect number of bindings supplied. The current statement uses 2, and there are 1 supplied.
2018-11-13 16:31:00,963 - ERROR - systemlog.py - log_error - 47 - Incorrect number of bindings supplied. The current statement uses 2, and there are 1 supplied.
2018-11-13 16:31:12,505 - ERROR - systemlog.py - log_error - 47 - Incorrect number of bindings supplied. The current statement uses 2, and there are 1 supplied.
2018-11-13 16:31:20,402 - ERROR - systemlog.py - log_error - 47 - Incorrect number of bindings supplied. The current statement uses 2, and there are 1 supplied.
2018-11-13 16:32:16,801 - ERROR - systemlog.py - log_error - 47 - Incorrect number of bindings supplied. The current statement uses 2, and there are 1 supplied.
2018-11-13 16:32:20,151 - ERROR - systemlog.py - log_error - 47 - Incorrect number of bindings supplied. The current statement uses 2, and there are 1 supplied.
2018-11-13 16:32:24,417 - ERROR - systemlog.py - log_error - 47 - Incorrect number of bindings supplied. The current statement uses 2, and there are 1 supplied.
2018-11-13 16:32:29,183 - ERROR - systemlog.py - log_error - 47 - Incorrect number of bindings supplied. The current statement uses 2, and there are 1 supplied.
2018-11-13 16:32:41,022 - ERROR - systemlog.py - log_error - 47 - Incorrect number of bindings supplied. The current statement uses 2, and there are 1 supplied.
2018-11-13 16:32:48,451 - ERROR - systemlog.py - log_error - 47 - Incorrect number of bindings supplied. The current statement uses 2, and there are 1 supplied.
2018-11-13 16:32:51,949 - ERROR - systemlog.py - log_error - 47 - Incorrect number of bindings supplied. The current statement uses 2, and there are 1 supplied.
2018-11-13 16:32:53,735 - ERROR - systemlog.py - log_error - 47 - Incorrect number of bindings supplied. The current statement uses 2, and there are 1 supplied.
2018-11-13 16:32:54,450 - ERROR - systemlog.py - log_error - 47 - Incorrect number of bindings supplied. The current statement uses 2, and there are 1 supplied.
2018-11-13 16:32:57,961 - ERROR - systemlog.py - log_error - 47 - Incorrect number of bindings supplied. The current statement uses 2, and there are 1 supplied.
2018-11-13 16:32:59,599 - ERROR - systemlog.py - log_error - 47 - Incorrect number of bindings supplied. The current statement uses 2, and there are 1 supplied.
2018-11-13 16:33:07,759 - ERROR - systemlog.py - log_error - 47 - Incorrect number of bindings supplied. The current statement uses 2, and there are 1 supplied.
2018-11-13 16:33:09,386 - ERROR - systemlog.py - log_error - 47 - Incorrect number of bindings supplied. The current statement uses 2, and there are 1 supplied.
2018-11-13 16:33:18,417 - ERROR - systemlog.py - log_error - 47 - Incorrect number of bindings supplied. The current statement uses 2, and there are 1 supplied.
2018-11-13 16:33:19,153 - ERROR - systemlog.py - log_error - 47 - Incorrect number of bindings supplied. The current statement uses 2, and there are 1 supplied.
2018-11-13 16:33:21,921 - ERROR - systemlog.py - log_error - 47 - Incorrect number of bindings supplied. The current statement uses 2, and there are 1 supplied.
2018-11-13 16:33:38,383 - ERROR - systemlog.py - log_error - 47 - Incorrect number of bindings supplied. The current statement uses 2, and there are 1 supplied.
2018-11-13 16:33:41,463 - ERROR - systemlog.py - log_error - 47 - Incorrect number of bindings supplied. The current statement uses 2, and there are 1 supplied.
2018-11-13 16:37:19,050 - ERROR - systemlog.py - log_error - 47 - Incorrect number of bindings supplied. The current statement uses 2, and there are 1 supplied.
2018-11-13 16:38:25,012 - ERROR - systemlog.py - log_error - 47 - Incorrect number of bindings supplied. The current statement uses 2, and there are 1 supplied.
2018-11-13 16:38:25,613 - ERROR - systemlog.py - log_error - 47 - Incorrect number of bindings supplied. The current statement uses 2, and there are 1 supplied.
2018-11-13 16:38:25,812 - ERROR - systemlog.py - log_error - 47 - Incorrect number of bindings supplied. The current statement uses 2, and there are 1 supplied.
2018-11-13 16:38:26,160 - ERROR - systemlog.py - log_error - 47 - Incorrect number of bindings supplied. The current statement uses 2, and there are 1 supplied.
2018-11-13 16:38:26,423 - ERROR - systemlog.py - log_error - 47 - Incorrect number of bindings supplied. The current statement uses 2, and there are 1 supplied.
2018-11-13 16:39:59,932 - ERROR - systemlog.py - log_error - 47 - Incorrect number of bindings supplied. The current statement uses 2, and there are 1 supplied.
2018-11-13 16:40:01,423 - ERROR - systemlog.py - log_error - 47 - Incorrect number of bindings supplied. The current statement uses 2, and there are 1 supplied.
2018-11-13 16:40:01,582 - ERROR - systemlog.py - log_error - 47 - Incorrect number of bindings supplied. The current statement uses 2, and there are 1 supplied.
2018-11-13 16:41:40,878 - ERROR - systemlog.py - log_error - 47 - Incorrect number of bindings supplied. The current statement uses 2, and there are 1 supplied.
2018-11-13 16:41:56,457 - ERROR - systemlog.py - log_error - 47 - Incorrect number of bindings supplied. The current statement uses 2, and there are 1 supplied.
2018-11-13 16:42:02,924 - ERROR - systemlog.py - log_error - 47 - Incorrect number of bindings supplied. The current statement uses 2, and there are 1 supplied.
2018-11-13 16:42:24,194 - ERROR - systemlog.py - log_error - 47 - Incorrect number of bindings supplied. The current statement uses 2, and there are 1 supplied.
2018-11-13 16:42:24,375 - ERROR - systemlog.py - log_error - 47 - Incorrect number of bindings supplied. The current statement uses 2, and there are 1 supplied.
2018-11-13 16:42:36,053 - ERROR - systemlog.py - log_error - 47 - Incorrect number of bindings supplied. The current statement uses 2, and there are 1 supplied.
2018-11-13 16:42:52,592 - ERROR - systemlog.py - log_error - 47 - Incorrect number of bindings supplied. The current statement uses 2, and there are 1 supplied.
2018-11-13 16:42:58,657 - ERROR - systemlog.py - log_error - 47 - Incorrect number of bindings supplied. The current statement uses 2, and there are 1 supplied.
2018-11-13 16:43:00,103 - ERROR - systemlog.py - log_error - 47 - Incorrect number of bindings supplied. The current statement uses 2, and there are 1 supplied.
2018-11-13 16:43:11,270 - ERROR - systemlog.py - log_error - 47 - Incorrect number of bindings supplied. The current statement uses 2, and there are 1 supplied.
2018-11-13 16:43:25,545 - ERROR - systemlog.py - log_error - 47 - Incorrect number of bindings supplied. The current statement uses 2, and there are 1 supplied.
2018-11-13 16:43:48,814 - ERROR - systemlog.py - log_error - 47 - Incorrect number of bindings supplied. The current statement uses 2, and there are 1 supplied.
2018-11-13 16:43:52,042 - ERROR - systemlog.py - log_error - 47 - Incorrect number of bindings supplied. The current statement uses 2, and there are 1 supplied.
2018-11-13 16:43:59,702 - ERROR - systemlog.py - log_error - 47 - Incorrect number of bindings supplied. The current statement uses 2, and there are 1 supplied.
2018-11-13 16:44:17,202 - ERROR - systemlog.py - log_error - 47 - Incorrect number of bindings supplied. The current statement uses 2, and there are 1 supplied.
2018-11-13 16:44:21,560 - ERROR - systemlog.py - log_error - 47 - Incorrect number of bindings supplied. The current statement uses 2, and there are 1 supplied.
2018-11-13 16:44:54,377 - ERROR - systemlog.py - log_error - 47 - Incorrect number of bindings supplied. The current statement uses 2, and there are 1 supplied.
2018-11-13 16:45:09,255 - ERROR - systemlog.py - log_error - 47 - Incorrect number of bindings supplied. The current statement uses 2, and there are 1 supplied.
2018-11-13 16:45:21,716 - ERROR - systemlog.py - log_error - 47 - Incorrect number of bindings supplied. The current statement uses 2, and there are 1 supplied.
2018-11-13 16:45:23,074 - ERROR - systemlog.py - log_error - 47 - Incorrect number of bindings supplied. The current statement uses 2, and there are 1 supplied.
2018-11-13 16:45:41,517 - ERROR - systemlog.py - log_error - 47 - Incorrect number of bindings supplied. The current statement uses 2, and there are 1 supplied.
2018-11-13 16:45:52,222 - ERROR - systemlog.py - log_error - 47 - Incorrect number of bindings supplied. The current statement uses 2, and there are 1 supplied.
2018-11-13 16:45:58,629 - ERROR - systemlog.py - log_error - 47 - Incorrect number of bindings supplied. The current statement uses 2, and there are 1 supplied.
2018-11-13 16:46:03,408 - ERROR - systemlog.py - log_error - 47 - Incorrect number of bindings supplied. The current statement uses 2, and there are 1 supplied.
2018-11-13 16:46:19,401 - ERROR - systemlog.py - log_error - 47 - Incorrect number of bindings supplied. The current statement uses 2, and there are 1 supplied.
2018-11-13 16:46:24,218 - ERROR - systemlog.py - log_error - 47 - Incorrect number of bindings supplied. The current statement uses 2, and there are 1 supplied.
2018-11-13 16:46:26,687 - ERROR - systemlog.py - log_error - 47 - Incorrect number of bindings supplied. The current statement uses 2, and there are 1 supplied.
2018-11-13 16:46:47,010 - ERROR - systemlog.py - log_error - 47 - Incorrect number of bindings supplied. The current statement uses 2, and there are 1 supplied.
2018-11-13 16:46:52,346 - ERROR - systemlog.py - log_error - 47 - Incorrect number of bindings supplied. The current statement uses 2, and there are 1 supplied.
2018-11-13 16:46:57,191 - ERROR - systemlog.py - log_error - 47 - Incorrect number of bindings supplied. The current statement uses 2, and there are 1 supplied.
2018-11-13 16:48:04,743 - ERROR - systemlog.py - log_error - 47 - Incorrect number of bindings supplied. The current statement uses 2, and there are 1 supplied.
2018-11-13 16:48:20,190 - ERROR - systemlog.py - log_error - 47 - Incorrect number of bindings supplied. The current statement uses 2, and there are 1 supplied.
2018-11-13 16:48:21,401 - ERROR - systemlog.py - log_error - 47 - Incorrect number of bindings supplied. The current statement uses 2, and there are 1 supplied.
2018-11-13 16:49:17,595 - ERROR - systemlog.py - log_error - 47 - Incorrect number of bindings supplied. The current statement uses 2, and there are 1 supplied.
2018-11-13 17:12:25,513 - ERROR - systemlog.py - log_error - 47 - FOREIGN KEY constraint failed
2018-11-13 17:12:30,617 - ERROR - systemlog.py - log_error - 47 - FOREIGN KEY constraint failed
2018-11-13 17:12:35,398 - ERROR - systemlog.py - log_error - 47 - FOREIGN KEY constraint failed
2018-11-13 17:28:32,804 - ERROR - systemlog.py - log_error - 47 - invalid literal for int() with base 10: '请先选择部门'
2018-11-13 17:28:40,759 - ERROR - systemlog.py - log_error - 47 - FOREIGN KEY constraint failed
2018-11-13 17:28:42,961 - ERROR - systemlog.py - log_error - 47 - FOREIGN KEY constraint failed
2018-11-15 09:31:06,828 - ERROR - systemlog.py - log_error - 47 - UNIQUE constraint failed: t_department.name
2018-11-15 09:34:36,114 - ERROR - systemlog.py - log_error - 47 - UNIQUE constraint failed: t_department.name, t_department.company_id
2018-11-16 15:54:50,155 - ERROR - systemlog.py - log_error - 47 - FOREIGN KEY constraint failed
2018-11-16 17:35:11,155 - ERROR - systemlog.py - log_error - 47 - 400 Bad Request: The browser (or proxy) sent a request that this server could not understand.
2018-11-16 17:39:17,331 - ERROR - systemlog.py - log_error - 47 - name 'getTime' is not defined
2018-11-16 17:40:45,398 - ERROR - systemlog.py - log_error - 47 - name 'getTime' is not defined
2018-11-16 17:41:04,596 - ERROR - systemlog.py - log_error - 47 - name 'getTime' is not defined
2018-11-19 10:29:01,843 - ERROR - systemlog.py - log_error - 47 - no such column: project_id
2018-11-26 16:58:19,761 - ERROR - systemlog.py - log_error - 47 - UNIQUE constraint failed: t_department.name, t_department.company_id
2018-11-27 10:17:47,052 - ERROR - systemlog.py - log_error - 47 - zip argument #2 must support iteration
2018-11-27 10:18:29,356 - ERROR - systemlog.py - log_error - 47 - zip argument #2 must support iteration
2018-11-27 10:19:10,561 - ERROR - systemlog.py - log_error - 47 - zip argument #2 must support iteration
2018-11-27 10:20:43,919 - ERROR - systemlog.py - log_error - 47 - name 'row' is not defined
2018-11-27 10:21:19,689 - ERROR - systemlog.py - log_error - 47 - dict expected at most 1 arguments, got 2
2018-11-27 10:22:09,581 - ERROR - systemlog.py - log_error - 47 - name 'row' is not defined
2018-11-27 17:02:57,596 - ERROR - systemlog.py - log_error - 47 - ambiguous column name: id
2018-11-27 17:03:25,957 - ERROR - systemlog.py - log_error - 47 - ambiguous column name: id
2018-11-30 09:12:23,313 - ERROR - systemlog.py - log_error - 47 - 提交工时出错
2018-11-30 11:42:47,928 - ERROR - systemlog.py - log_error - 47 - 提交工时出错
2018-11-30 12:01:31,607 - ERROR - systemlog.py - log_error - 47 - 提交工时出错
2018-12-04 10:28:18,332 - ERROR - systemlog.py - log_error - 47 - 部门id错误
2018-12-04 10:29:50,597 - ERROR - systemlog.py - log_error - 47 - 项目id错误
2018-12-04 10:29:59,657 - ERROR - systemlog.py - log_error - 47 - 项目id错误
2018-12-04 10:41:25,715 - ERROR - systemlog.py - log_error - 47 - 项目id错误
2018-12-04 10:56:29,926 - ERROR - systemlog.py - log_error - 47 - 400 Bad Request: The browser (or proxy) sent a request that this server could not understand.
2018-12-05 13:01:46,507 - ERROR - systemlog.py - log_error - 47 - could not convert string to float: 
2018-12-05 13:07:51,824 - ERROR - systemlog.py - log_error - 47 - 部门名称不能为空
2018-12-05 13:20:50,558 - ERROR - systemlog.py - log_error - 47 - 部门id错误
2018-12-05 13:21:04,819 - ERROR - systemlog.py - log_error - 47 - 部门id错误
2018-12-05 13:22:27,679 - ERROR - systemlog.py - log_error - 47 - 部门id错误
2018-12-05 14:03:38,310 - ERROR - systemlog.py - log_error - 47 - 部门名称不能为空
2018-12-05 14:04:42,641 - ERROR - systemlog.py - log_error - 47 - 部门名称不能为空
2018-12-05 14:04:46,674 - ERROR - systemlog.py - log_error - 47 - 部门名称不能为空
2018-12-06 13:58:38,766 - ERROR - systemlog.py - log_error - 47 - 提交工时出错
2018-12-06 13:58:44,677 - ERROR - systemlog.py - log_error - 47 - 提交工时出错
2018-12-06 17:03:03,524 - ERROR - systemlog.py - log_error - 47 - could not convert string to float: 
2018-12-10 13:56:31,164 - ERROR - systemlog.py - log_error - 47 - could not convert string to float: 
2018-12-12 13:01:29,023 - INFO - systemlog.py - log_info - 35 - 未发现数据库...

2018-12-12 13:01:29,031 - INFO - systemlog.py - log_info - 35 - 准备初始化数据库...

2018-12-12 13:13:02,447 - INFO - systemlog.py - log_info - 35 - 未发现数据库...

2018-12-12 13:13:02,447 - INFO - systemlog.py - log_info - 35 - 准备初始化数据库...

2018-12-12 13:13:02,463 - INFO - systemlog.py - log_info - 35 - 数据库初始化完成...
2018-12-12 13:13:02,471 - INFO - systemlog.py - log_info - 35 - 数据库初始化完成...
2018-12-12 13:13:02,480 - INFO - systemlog.py - log_info - 35 - 数据库初始化完成...
2018-12-12 13:13:02,501 - INFO - systemlog.py - log_info - 35 - 数据库初始化完成...
2018-12-12 13:13:02,519 - INFO - systemlog.py - log_info - 35 - 数据库初始化完成...
2018-12-12 13:13:02,519 - ERROR - systemlog.py - log_error - 47 - (sqlite3.OperationalError) near ""id"": syntax error [SQL: '"id"  INTEGER PRIMARY KEY AUTOINCREMENT NOT NULL,\n"user_id"  INTEGER NOT NULL,\n"project_id"  TEXT NOT NULL,\n"worktime"  REAL NOT NULL,\n"date"  TEXT NOT NULL,\n"time"  TEXT,\nCONSTRAINT "fkey0" FOREIGN KEY ("user_id") REFERENCES "t_user" ("id"),\nCONSTRAINT "fkey1" FOREIGN KEY ("project_id") REFERENCES "t_project" ("id"),\nUNIQUE ("user_id" ASC, "project_id" ASC, "date" ASC)\n);'] (Background on this error at: http://sqlalche.me/e/e3q8)
2018-12-12 13:13:02,520 - INFO - systemlog.py - log_info - 35 - 数据库初始化完成...
2018-12-12 13:16:16,460 - INFO - systemlog.py - log_info - 35 - 未发现数据库...

2018-12-12 13:16:16,461 - INFO - systemlog.py - log_info - 35 - 准备初始化数据库...

2018-12-12 13:16:16,512 - ERROR - systemlog.py - log_error - 47 - (sqlite3.OperationalError) near ""id"": syntax error [SQL: '"id"  INTEGER PRIMARY KEY AUTOINCREMENT NOT NULL,\n"user_id"  INTEGER NOT NULL,\n"project_id"  TEXT NOT NULL,\n"worktime"  REAL NOT NULL,\n"date"  TEXT NOT NULL,\n"time"  TEXT,\nCONSTRAINT "fkey0" FOREIGN KEY ("user_id") REFERENCES "t_user" ("id"),\nCONSTRAINT "fkey1" FOREIGN KEY ("project_id") REFERENCES "t_project" ("id"),\nUNIQUE ("user_id" ASC, "project_id" ASC, "date" ASC)\n);'] (Background on this error at: http://sqlalche.me/e/e3q8)
2018-12-12 13:16:16,513 - INFO - systemlog.py - log_info - 35 - 数据库初始化完成...
2018-12-12 13:18:48,779 - INFO - systemlog.py - log_info - 35 - 未发现数据库...

2018-12-12 13:18:48,779 - INFO - systemlog.py - log_info - 35 - 准备初始化数据库...

2018-12-12 13:18:48,845 - INFO - systemlog.py - log_info - 35 - 数据库初始化完成...
2018-12-19 14:00:40,141 - ERROR - systemlog.py - log_error - 47 - 400 Bad Request: The browser (or proxy) sent a request that this server could not understand.
2018-12-19 14:02:07,260 - ERROR - systemlog.py - log_error - 47 - 400 Bad Request: The browser (or proxy) sent a request that this server could not understand.
2018-12-20 09:18:50,683 - ERROR - systemlog.py - log_error - 47 - 400 Bad Request: The browser (or proxy) sent a request that this server could not understand.
2018-12-20 09:25:17,129 - ERROR - systemlog.py - log_error - 47 - 400 Bad Request: The browser (or proxy) sent a request that this server could not understand.
2018-12-20 09:27:53,652 - ERROR - systemlog.py - log_error - 47 - 400 Bad Request: The browser (or proxy) sent a request that this server could not understand.
2018-12-20 09:46:49,283 - ERROR - systemlog.py - log_error - 47 - 'NoneType' object is not iterable
2018-12-20 09:46:49,304 - ERROR - systemlog.py - log_error - 47 - 'NoneType' object is not iterable
2018-12-20 09:46:49,323 - ERROR - systemlog.py - log_error - 47 - 'NoneType' object is not iterable
2018-12-20 09:46:49,337 - ERROR - systemlog.py - log_error - 47 - 'NoneType' object is not iterable
2018-12-20 09:46:49,346 - ERROR - systemlog.py - log_error - 47 - 'NoneType' object is not iterable
2018-12-20 09:46:49,356 - ERROR - systemlog.py - log_error - 47 - 'NoneType' object is not iterable
2018-12-20 09:57:43,898 - ERROR - systemlog.py - log_error - 47 - 'NoneType' object is not iterable
2018-12-20 09:57:46,266 - ERROR - systemlog.py - log_error - 47 - 'NoneType' object is not iterable
2018-12-20 09:57:47,308 - ERROR - systemlog.py - log_error - 47 - 'NoneType' object is not iterable
2018-12-20 09:58:15,843 - ERROR - systemlog.py - log_error - 47 - 'NoneType' object is not iterable
2018-12-20 10:37:50,570 - ERROR - systemlog.py - log_error - 47 - (102, b"Incorrect syntax near 'h'.DB-Lib error message 20018, severity 15:\nGeneral SQL Server error: Check messages from the SQL Server\nDB-Lib error message 20018, severity 15:\nGeneral SQL Server error: Check messages from the SQL Server\n")
2018-12-20 10:37:52,403 - ERROR - systemlog.py - log_error - 47 - (102, b"Incorrect syntax near 'j'.DB-Lib error message 20018, severity 15:\nGeneral SQL Server error: Check messages from the SQL Server\nDB-Lib error message 20018, severity 15:\nGeneral SQL Server error: Check messages from the SQL Server\n")
2018-12-20 12:00:21,304 - INFO - systemlog.py - log_info - 35 - 未发现数据库...

2018-12-20 12:00:21,304 - INFO - systemlog.py - log_info - 35 - 准备初始化数据库...

2018-12-20 12:00:21,378 - INFO - systemlog.py - log_info - 35 - 数据库初始化完成...
2018-12-21 09:16:30,461 - ERROR - systemlog.py - log_error - 47 - (102, b"Incorrect syntax near 'f'.DB-Lib error message 20018, severity 15:\nGeneral SQL Server error: Check messages from the SQL Server\nDB-Lib error message 20018, severity 15:\nGeneral SQL Server error: Check messages from the SQL Server\n")
2018-12-21 09:16:30,483 - ERROR - systemlog.py - log_error - 47 - (102, b"Incorrect syntax near 'f'.DB-Lib error message 20018, severity 15:\nGeneral SQL Server error: Check messages from the SQL Server\n")
2018-12-21 09:16:30,587 - ERROR - systemlog.py - log_error - 47 - (102, b"Incorrect syntax near 'f'.DB-Lib error message 20018, severity 15:\nGeneral SQL Server error: Check messages from the SQL Server\nDB-Lib error message 20018, severity 15:\nGeneral SQL Server error: Check messages from the SQL Server\n")
2018-12-21 09:16:30,652 - ERROR - systemlog.py - log_error - 47 - (102, b"Incorrect syntax near 'f'.DB-Lib error message 20018, severity 15:\nGeneral SQL Server error: Check messages from the SQL Server\n")
2018-12-21 09:16:30,739 - ERROR - systemlog.py - log_error - 47 - (102, b"Incorrect syntax near 'f'.DB-Lib error message 20018, severity 15:\nGeneral SQL Server error: Check messages from the SQL Server\nDB-Lib error message 20018, severity 15:\nGeneral SQL Server error: Check messages from the SQL Server\n")
2018-12-21 15:03:40,579 - ERROR - systemlog.py - log_error - 47 - module 'whmgsystem.model.itemTable' has no attribute 'id'
2018-12-21 15:56:26,011 - ERROR - systemlog.py - log_error - 47 - invalid literal for int() with base 10: ''
2018-12-21 15:57:02,213 - ERROR - systemlog.py - log_error - 47 - invalid literal for int() with base 10: ''
2018-12-21 15:57:09,899 - ERROR - systemlog.py - log_error - 47 - invalid literal for int() with base 10: ''
2018-12-21 15:58:05,789 - ERROR - systemlog.py - log_error - 47 - invalid literal for int() with base 10: ''
2018-12-24 11:15:04,826 - ERROR - systemlog.py - log_error - 47 - (102, b"Incorrect syntax near 'z'.DB-Lib error message 20018, severity 15:\nGeneral SQL Server error: Check messages from the SQL Server\nDB-Lib error message 20018, severity 15:\nGeneral SQL Server error: Check messages from the SQL Server\n")
2018-12-24 11:15:04,910 - ERROR - systemlog.py - log_error - 47 - (102, b"Incorrect syntax near 'zi'.DB-Lib error message 20018, severity 15:\nGeneral SQL Server error: Check messages from the SQL Server\nDB-Lib error message 20018, severity 15:\nGeneral SQL Server error: Check messages from the SQL Server\n")
2018-12-24 11:15:06,243 - ERROR - systemlog.py - log_error - 47 - (102, b"Incorrect syntax near 'z'.DB-Lib error message 20018, severity 15:\nGeneral SQL Server error: Check messages from the SQL Server\nDB-Lib error message 20018, severity 15:\nGeneral SQL Server error: Check messages from the SQL Server\n")
2018-12-24 11:15:06,435 - ERROR - systemlog.py - log_error - 47 - (102, b"Incorrect syntax near 'z'.DB-Lib error message 20018, severity 15:\nGeneral SQL Server error: Check messages from the SQL Server\n")
2018-12-24 11:15:06,538 - ERROR - systemlog.py - log_error - 47 - (102, b"Incorrect syntax near 'z'.DB-Lib error message 20018, severity 15:\nGeneral SQL Server error: Check messages from the SQL Server\nDB-Lib error message 20018, severity 15:\nGeneral SQL Server error: Check messages from the SQL Server\n")
2018-12-24 11:15:06,634 - ERROR - systemlog.py - log_error - 47 - (102, b"Incorrect syntax near 'z'.DB-Lib error message 20018, severity 15:\nGeneral SQL Server error: Check messages from the SQL Server\nDB-Lib error message 20018, severity 15:\nGeneral SQL Server error: Check messages from the SQL Server\n")
2018-12-24 11:15:08,694 - ERROR - systemlog.py - log_error - 47 - (102, b"Incorrect syntax near 'c'.DB-Lib error message 20018, severity 15:\nGeneral SQL Server error: Check messages from the SQL Server\nDB-Lib error message 20018, severity 15:\nGeneral SQL Server error: Check messages from the SQL Server\n")
2018-12-24 11:15:08,822 - ERROR - systemlog.py - log_error - 47 - (102, b"Incorrect syntax near 'ci'.DB-Lib error message 20018, severity 15:\nGeneral SQL Server error: Check messages from the SQL Server\nDB-Lib error message 20018, severity 15:\nGeneral SQL Server error: Check messages from the SQL Server\n")
2018-12-24 12:39:03,959 - ERROR - systemlog.py - log_error - 47 - 'NoneType' object is not iterable
2018-12-24 12:39:03,972 - ERROR - systemlog.py - log_error - 47 - 'NoneType' object is not iterable
2018-12-24 12:39:05,792 - ERROR - systemlog.py - log_error - 47 - 'NoneType' object is not iterable
2018-12-24 12:39:06,674 - ERROR - systemlog.py - log_error - 47 - 'NoneType' object is not iterable
2018-12-24 12:39:07,500 - ERROR - systemlog.py - log_error - 47 - 'NoneType' object is not iterable
2018-12-24 12:39:08,121 - ERROR - systemlog.py - log_error - 47 - 'NoneType' object is not iterable
2018-12-24 12:39:08,859 - ERROR - systemlog.py - log_error - 47 - 'NoneType' object is not iterable
2018-12-24 12:39:09,662 - ERROR - systemlog.py - log_error - 47 - 'NoneType' object is not iterable
2018-12-24 12:39:09,733 - ERROR - systemlog.py - log_error - 47 - 'NoneType' object is not iterable
2018-12-24 12:39:09,857 - ERROR - systemlog.py - log_error - 47 - 'NoneType' object is not iterable
2018-12-24 12:39:09,929 - ERROR - systemlog.py - log_error - 47 - 'NoneType' object is not iterable
2018-12-24 12:39:10,106 - ERROR - systemlog.py - log_error - 47 - 'NoneType' object is not iterable
2018-12-24 12:39:10,428 - ERROR - systemlog.py - log_error - 47 - 'NoneType' object is not iterable
2018-12-24 12:39:10,563 - ERROR - systemlog.py - log_error - 47 - 'NoneType' object is not iterable
2018-12-24 12:39:10,681 - ERROR - systemlog.py - log_error - 47 - 'NoneType' object is not iterable
2018-12-24 12:39:10,820 - ERROR - systemlog.py - log_error - 47 - 'NoneType' object is not iterable
2018-12-24 12:39:10,964 - ERROR - systemlog.py - log_error - 47 - 'NoneType' object is not iterable
2018-12-24 12:39:11,487 - ERROR - systemlog.py - log_error - 47 - 'NoneType' object is not iterable
2018-12-24 12:39:11,654 - ERROR - systemlog.py - log_error - 47 - 'NoneType' object is not iterable
2018-12-24 12:39:11,821 - ERROR - systemlog.py - log_error - 47 - 'NoneType' object is not iterable
2018-12-24 12:39:11,917 - ERROR - systemlog.py - log_error - 47 - 'NoneType' object is not iterable
2018-12-24 12:39:12,248 - ERROR - systemlog.py - log_error - 47 - 'NoneType' object is not iterable
2018-12-24 12:39:12,573 - ERROR - systemlog.py - log_error - 47 - 'NoneType' object is not iterable
2018-12-24 12:39:12,765 - ERROR - systemlog.py - log_error - 47 - 'NoneType' object is not iterable
2018-12-24 12:39:12,894 - ERROR - systemlog.py - log_error - 47 - 'NoneType' object is not iterable
2018-12-24 12:39:13,030 - ERROR - systemlog.py - log_error - 47 - 'NoneType' object is not iterable
2018-12-24 12:39:13,134 - ERROR - systemlog.py - log_error - 47 - 'NoneType' object is not iterable
2018-12-24 12:39:13,389 - ERROR - systemlog.py - log_error - 47 - 'NoneType' object is not iterable
2018-12-24 12:39:13,766 - ERROR - systemlog.py - log_error - 47 - 'NoneType' object is not iterable
2018-12-24 12:39:13,916 - ERROR - systemlog.py - log_error - 47 - 'NoneType' object is not iterable
2018-12-24 12:39:14,025 - ERROR - systemlog.py - log_error - 47 - 'NoneType' object is not iterable
2018-12-24 12:39:14,135 - ERROR - systemlog.py - log_error - 47 - 'NoneType' object is not iterable
2018-12-24 12:39:14,215 - ERROR - systemlog.py - log_error - 47 - 'NoneType' object is not iterable
2018-12-24 12:39:15,065 - ERROR - systemlog.py - log_error - 47 - 'NoneType' object is not iterable
2018-12-24 12:39:16,778 - ERROR - systemlog.py - log_error - 47 - 'NoneType' object is not iterable
2018-12-24 12:39:57,957 - ERROR - systemlog.py - log_error - 47 - 'NoneType' object is not iterable
2018-12-24 12:39:58,006 - ERROR - systemlog.py - log_error - 47 - 'NoneType' object is not iterable
2018-12-24 12:39:59,211 - ERROR - systemlog.py - log_error - 47 - 'NoneType' object is not iterable
2018-12-24 12:39:59,717 - ERROR - systemlog.py - log_error - 47 - 'NoneType' object is not iterable
2018-12-24 12:40:03,234 - ERROR - systemlog.py - log_error - 47 - 'NoneType' object is not iterable
2018-12-24 13:43:16,838 - ERROR - systemlog.py - log_error - 47 - could not convert string to float: 
2018-12-25 11:49:54,060 - INFO - systemlog.py - log_info - 35 - 未发现数据库...

2018-12-25 11:49:54,061 - INFO - systemlog.py - log_info - 35 - 准备初始化数据库...

2018-12-25 11:49:54,128 - INFO - systemlog.py - log_info - 35 - 数据库初始化完成...
2018-12-25 13:45:49,557 - INFO - systemlog.py - log_info - 35 - 未发现数据库...

2018-12-25 13:45:49,558 - INFO - systemlog.py - log_info - 35 - 准备初始化数据库...

2018-12-25 13:45:49,639 - INFO - systemlog.py - log_info - 35 - 数据库初始化完成...
2018-12-25 13:47:54,546 - INFO - systemlog.py - log_info - 35 - 未发现数据库...

2018-12-25 13:47:54,546 - INFO - systemlog.py - log_info - 35 - 准备初始化数据库...

2018-12-25 13:47:54,643 - INFO - systemlog.py - log_info - 35 - 数据库初始化完成...
2018-12-25 13:49:59,273 - INFO - systemlog.py - log_info - 35 - 未发现数据库...

2018-12-25 13:49:59,274 - INFO - systemlog.py - log_info - 35 - 准备初始化数据库...

2018-12-25 13:49:59,349 - INFO - systemlog.py - log_info - 35 - 数据库初始化完成...
2018-12-26 09:18:51,911 - INFO - systemlog.py - log_info - 35 - 未发现数据库...

2018-12-26 09:18:51,912 - INFO - systemlog.py - log_info - 35 - 准备初始化数据库...

2018-12-26 09:18:52,014 - INFO - systemlog.py - log_info - 35 - 数据库初始化完成...
2018-12-26 17:02:10,678 - INFO - systemlog.py - log_info - 35 - 未发现数据库...

2018-12-26 17:02:10,686 - INFO - systemlog.py - log_info - 35 - 准备初始化数据库...

2018-12-26 17:02:10,760 - INFO - systemlog.py - log_info - 35 - 数据库初始化完成...
2018-12-26 17:03:45,307 - INFO - systemlog.py - log_info - 35 - 未发现数据库...

2018-12-26 17:03:45,308 - INFO - systemlog.py - log_info - 35 - 准备初始化数据库...

2018-12-26 17:03:45,389 - INFO - systemlog.py - log_info - 35 - 数据库初始化完成...
2018-12-28 09:32:10,804 - INFO - systemlog.py - log_info - 35 - 未发现数据库...

2018-12-28 09:32:10,812 - INFO - systemlog.py - log_info - 35 - 准备初始化数据库...

2018-12-28 09:32:10,904 - INFO - systemlog.py - log_info - 35 - 数据库初始化完成...
2018-12-28 10:59:09,256 - ERROR - systemlog.py - log_error - 47 - Class 'builtins.NoneType' is not mapped
2018-12-28 11:00:09,692 - ERROR - systemlog.py - log_error - 47 - Class 'builtins.NoneType' is not mapped
2018-12-28 11:17:15,861 - ERROR - systemlog.py - log_error - 47 - (102, b"Incorrect syntax near 'd'.DB-Lib error message 20018, severity 15:\nGeneral SQL Server error: Check messages from the SQL Server\nDB-Lib error message 20018, severity 15:\nGeneral SQL Server error: Check messages from the SQL Server\n")
2018-12-28 11:17:16,053 - ERROR - systemlog.py - log_error - 47 - (102, b"Incorrect syntax near 'di'.DB-Lib error message 20018, severity 15:\nGeneral SQL Server error: Check messages from the SQL Server\nDB-Lib error message 20018, severity 15:\nGeneral SQL Server error: Check messages from the SQL Server\n")
2018-12-28 11:17:16,139 - ERROR - systemlog.py - log_error - 47 - (102, b"Incorrect syntax near 'din'.DB-Lib error message 20018, severity 15:\nGeneral SQL Server error: Check messages from the SQL Server\nDB-Lib error message 20018, severity 15:\nGeneral SQL Server error: Check messages from the SQL Server\n")
2018-12-28 11:17:16,221 - ERROR - systemlog.py - log_error - 47 - (102, b"Incorrect syntax near 'ding'.DB-Lib error message 20018, severity 15:\nGeneral SQL Server error: Check messages from the SQL Server\nDB-Lib error message 20018, severity 15:\nGeneral SQL Server error: Check messages from the SQL Server\n")
2018-12-29 10:42:33,079 - ERROR - systemlog.py - log_error - 47 - 400 Bad Request: The browser (or proxy) sent a request that this server could not understand.
2018-12-29 10:43:59,751 - ERROR - systemlog.py - log_error - 47 - 400 Bad Request: The browser (or proxy) sent a request that this server could not understand.
2019-01-02 12:45:15,828 - ERROR - systemlog.py - log_error - 47 - 'NoneType' object is not iterable
2019-01-02 12:45:17,432 - ERROR - systemlog.py - log_error - 47 - 'NoneType' object is not iterable
2019-01-02 12:45:17,438 - ERROR - systemlog.py - log_error - 47 - 'NoneType' object is not iterable
2019-01-02 12:45:17,951 - ERROR - systemlog.py - log_error - 47 - 'NoneType' object is not iterable
2019-01-02 12:45:18,757 - ERROR - systemlog.py - log_error - 47 - 'NoneType' object is not iterable
2019-01-02 12:45:20,719 - ERROR - systemlog.py - log_error - 47 - 'NoneType' object is not iterable
2019-01-02 12:45:21,953 - ERROR - systemlog.py - log_error - 47 - 'NoneType' object is not iterable
2019-01-02 12:45:22,622 - ERROR - systemlog.py - log_error - 47 - 'NoneType' object is not iterable
2019-01-02 12:45:22,636 - ERROR - systemlog.py - log_error - 47 - 'NoneType' object is not iterable
2019-01-02 12:45:22,844 - ERROR - systemlog.py - log_error - 47 - 'NoneType' object is not iterable
2019-01-02 12:45:23,670 - ERROR - systemlog.py - log_error - 47 - 'NoneType' object is not iterable
2019-01-02 12:45:23,853 - ERROR - systemlog.py - log_error - 47 - 'NoneType' object is not iterable
2019-01-02 12:45:24,029 - ERROR - systemlog.py - log_error - 47 - 'NoneType' object is not iterable
2019-01-02 12:45:38,553 - ERROR - systemlog.py - log_error - 47 - 'NoneType' object is not iterable
2019-01-02 13:05:15,626 - ERROR - systemlog.py - log_error - 47 - (209, b"Ambiguous column name 'FItemID'.DB-Lib error message 20018, severity 16:\nGeneral SQL Server error: Check messages from the SQL Server\n")
2019-01-02 13:05:15,674 - ERROR - systemlog.py - log_error - 47 - (209, b"Ambiguous column name 'FItemID'.DB-Lib error message 20018, severity 16:\nGeneral SQL Server error: Check messages from the SQL Server\n")
2019-01-02 13:05:15,727 - ERROR - systemlog.py - log_error - 47 - (209, b"Ambiguous column name 'FItemID'.DB-Lib error message 20018, severity 16:\nGeneral SQL Server error: Check messages from the SQL Server\n")
2019-01-02 13:05:40,614 - ERROR - systemlog.py - log_error - 47 - (209, b"Ambiguous column name 'FItemID'.DB-Lib error message 20018, severity 16:\nGeneral SQL Server error: Check messages from the SQL Server\n")
2019-01-02 13:05:40,674 - ERROR - systemlog.py - log_error - 47 - (209, b"Ambiguous column name 'FItemID'.DB-Lib error message 20018, severity 16:\nGeneral SQL Server error: Check messages from the SQL Server\n")
2019-01-02 13:05:40,721 - ERROR - systemlog.py - log_error - 47 - (209, b"Ambiguous column name 'FItemID'.DB-Lib error message 20018, severity 16:\nGeneral SQL Server error: Check messages from the SQL Server\n")
2019-01-02 15:01:37,178 - INFO - systemlog.py - log_info - 35 - 未发现数据库...

2019-01-02 15:01:37,178 - INFO - systemlog.py - log_info - 35 - 准备初始化数据库...

2019-01-02 15:01:37,278 - INFO - systemlog.py - log_info - 35 - 数据库初始化完成...
2019-01-04 11:16:10,727 - INFO - systemlog.py - log_info - 35 - 未发现数据库...

2019-01-04 11:16:10,735 - INFO - systemlog.py - log_info - 35 - 准备初始化数据库...

2019-01-04 11:16:10,820 - INFO - systemlog.py - log_info - 35 - 数据库初始化完成...
2019-01-04 11:45:37,137 - ERROR - systemlog.py - log_error - 47 - (sqlite3.IntegrityError) NOT NULL constraint failed: t_project.super_user_id [SQL: 'UPDATE t_project SET super_user_id=? WHERE t_project.id = ?'] [parameters: (None, '是否')] (Background on this error at: http://sqlalche.me/e/gkpj)
2019-01-04 11:56:08,171 - ERROR - systemlog.py - log_error - 47 - object of type 'NoneType' has no len()
2019-01-04 11:56:18,120 - ERROR - systemlog.py - log_error - 47 - object of type 'NoneType' has no len()
2019-01-04 11:56:30,260 - ERROR - systemlog.py - log_error - 47 - object of type 'NoneType' has no len()
2019-01-04 13:52:09,629 - ERROR - systemlog.py - log_error - 47 - invalid literal for int() with base 10: ''
2019-01-04 13:56:01,635 - ERROR - systemlog.py - log_error - 47 - object of type 'NoneType' has no len()
2019-01-14 14:37:34,647 - ERROR - systemlog.py - log_error - 47 - (229, b"The SELECT permission was denied on the object 'ICInventory', database 'AIS20171226111824', schema 'dbo'.DB-Lib error message 20018, severity 14:\nGeneral SQL Server error: Check messages from the SQL Server\n")
2019-01-14 14:37:35,634 - ERROR - systemlog.py - log_error - 47 - (229, b"The SELECT permission was denied on the object 'ICInventory', database 'AIS20171226111824', schema 'dbo'.DB-Lib error message 20018, severity 14:\nGeneral SQL Server error: Check messages from the SQL Server\n")
2019-01-14 14:42:37,750 - ERROR - systemlog.py - log_error - 47 - (229, b"The SELECT permission was denied on the object 'ICInventory', database 'AIS20171226111824', schema 'dbo'.DB-Lib error message 20018, severity 14:\nGeneral SQL Server error: Check messages from the SQL Server\n")
2019-01-14 14:42:39,358 - ERROR - systemlog.py - log_error - 47 - (229, b"The SELECT permission was denied on the object 'ICInventory', database 'AIS20171226111824', schema 'dbo'.DB-Lib error message 20018, severity 14:\nGeneral SQL Server error: Check messages from the SQL Server\n")
2019-01-14 16:35:30,781 - ERROR - systemlog.py - log_error - 47 - object of type 'NoneType' has no len()
2019-01-14 17:31:27,289 - ERROR - systemlog.py - log_error - 47 - object of type 'NoneType' has no len()
2019-01-14 17:34:34,536 - ERROR - systemlog.py - log_error - 47 - object of type 'NoneType' has no len()
2019-01-14 17:34:34,943 - ERROR - systemlog.py - log_error - 47 - object of type 'NoneType' has no len()
2019-01-14 17:34:38,151 - ERROR - systemlog.py - log_error - 47 - object of type 'NoneType' has no len()
2019-01-14 17:34:40,159 - ERROR - systemlog.py - log_error - 47 - object of type 'NoneType' has no len()
2019-01-14 17:34:42,204 - ERROR - systemlog.py - log_error - 47 - object of type 'NoneType' has no len()
2019-01-14 17:42:06,918 - ERROR - systemlog.py - log_error - 47 - object of type 'NoneType' has no len()
2019-01-14 17:42:45,958 - ERROR - systemlog.py - log_error - 47 - object of type 'NoneType' has no len()
2019-01-14 17:46:24,456 - ERROR - systemlog.py - log_error - 47 - object of type 'NoneType' has no len()
2019-01-14 17:47:01,333 - ERROR - systemlog.py - log_error - 47 - object of type 'NoneType' has no len()
2019-01-14 17:48:04,779 - ERROR - systemlog.py - log_error - 47 - object of type 'NoneType' has no len()
2019-01-14 17:48:25,958 - ERROR - systemlog.py - log_error - 47 - object of type 'NoneType' has no len()
2019-01-16 15:12:38,308 - ERROR - systemlog.py - log_error - 47 - 400 Bad Request: The browser (or proxy) sent a request that this server could not understand.
2019-01-16 15:14:20,433 - ERROR - systemlog.py - log_error - 47 - 400 Bad Request: The browser (or proxy) sent a request that this server could not understand.
2019-01-16 15:14:51,969 - ERROR - systemlog.py - log_error - 47 - 400 Bad Request: The browser (or proxy) sent a request that this server could not understand.
2019-01-16 15:39:10,724 - ERROR - systemlog.py - log_error - 47 - (102, b"Incorrect syntax near '.0029'.DB-Lib error message 20018, severity 15:\nGeneral SQL Server error: Check messages from the SQL Server\n")
2019-01-16 15:39:10,849 - ERROR - systemlog.py - log_error - 47 - (102, b"Incorrect syntax near '.0023'.DB-Lib error message 20018, severity 15:\nGeneral SQL Server error: Check messages from the SQL Server\n")
2019-01-16 15:40:51,548 - ERROR - systemlog.py - log_error - 47 - (102, b"Incorrect syntax near '.0029'.DB-Lib error message 20018, severity 15:\nGeneral SQL Server error: Check messages from the SQL Server\n")
2019-01-16 15:40:51,556 - ERROR - systemlog.py - log_error - 47 - (102, b"Incorrect syntax near '.0023'.DB-Lib error message 20018, severity 15:\nGeneral SQL Server error: Check messages from the SQL Server\n")
2019-01-16 15:42:03,999 - ERROR - systemlog.py - log_error - 47 - (102, b"Incorrect syntax near '.0029'.DB-Lib error message 20018, severity 15:\nGeneral SQL Server error: Check messages from the SQL Server\n")
2019-01-16 15:42:04,007 - ERROR - systemlog.py - log_error - 47 - (102, b"Incorrect syntax near '.0023'.DB-Lib error message 20018, severity 15:\nGeneral SQL Server error: Check messages from the SQL Server\n")
2019-01-17 10:53:41,808 - ERROR - systemlog.py - log_error - 47 - 'NoneType' object is not iterable
2019-01-17 10:53:41,810 - ERROR - systemlog.py - log_error - 47 - 'NoneType' object is not iterable
2019-01-17 10:53:41,811 - ERROR - systemlog.py - log_error - 47 - 'NoneType' object is not iterable
2019-01-17 10:53:41,813 - ERROR - systemlog.py - log_error - 47 - 'NoneType' object is not iterable
2019-01-17 10:53:41,814 - ERROR - systemlog.py - log_error - 47 - 'NoneType' object is not iterable
2019-01-17 10:53:41,814 - ERROR - systemlog.py - log_error - 47 - 'NoneType' object is not iterable
2019-01-17 10:53:41,816 - ERROR - systemlog.py - log_error - 47 - 'NoneType' object is not iterable
2019-01-17 10:53:41,818 - ERROR - systemlog.py - log_error - 47 - 'NoneType' object is not iterable
2019-01-17 10:53:41,820 - ERROR - systemlog.py - log_error - 47 - 'NoneType' object is not iterable
2019-01-17 10:53:41,821 - ERROR - systemlog.py - log_error - 47 - 'NoneType' object is not iterable
2019-01-17 10:53:41,822 - ERROR - systemlog.py - log_error - 47 - 'NoneType' object is not iterable
2019-01-17 10:53:41,823 - ERROR - systemlog.py - log_error - 47 - 'NoneType' object is not iterable
2019-01-17 10:53:41,824 - ERROR - systemlog.py - log_error - 47 - 'NoneType' object is not iterable
2019-01-17 10:53:41,825 - ERROR - systemlog.py - log_error - 47 - 'NoneType' object is not iterable
2019-01-17 10:53:41,826 - ERROR - systemlog.py - log_error - 47 - 'NoneType' object is not iterable
2019-01-17 10:53:41,827 - ERROR - systemlog.py - log_error - 47 - 'NoneType' object is not iterable
2019-01-17 10:53:41,828 - ERROR - systemlog.py - log_error - 47 - 'NoneType' object is not iterable
2019-01-17 10:53:41,828 - ERROR - systemlog.py - log_error - 47 - 'NoneType' object is not iterable
2019-01-17 10:53:41,829 - ERROR - systemlog.py - log_error - 47 - 'NoneType' object is not iterable
2019-01-17 10:53:41,830 - ERROR - systemlog.py - log_error - 47 - 'NoneType' object is not iterable
2019-01-17 10:53:41,832 - ERROR - systemlog.py - log_error - 47 - 'NoneType' object is not iterable
2019-01-17 10:53:41,834 - ERROR - systemlog.py - log_error - 47 - 'NoneType' object is not iterable
2019-01-17 10:53:41,836 - ERROR - systemlog.py - log_error - 47 - 'NoneType' object is not iterable
2019-01-17 10:53:41,837 - ERROR - systemlog.py - log_error - 47 - 'NoneType' object is not iterable
2019-01-17 10:53:41,838 - ERROR - systemlog.py - log_error - 47 - 'NoneType' object is not iterable
2019-01-17 10:53:41,839 - ERROR - systemlog.py - log_error - 47 - 'NoneType' object is not iterable
2019-01-17 10:53:41,841 - ERROR - systemlog.py - log_error - 47 - 'NoneType' object is not iterable
2019-01-17 10:53:41,842 - ERROR - systemlog.py - log_error - 47 - 'NoneType' object is not iterable
2019-01-17 10:53:41,843 - ERROR - systemlog.py - log_error - 47 - 'NoneType' object is not iterable
2019-01-17 10:53:41,844 - ERROR - systemlog.py - log_error - 47 - 'NoneType' object is not iterable
2019-01-17 10:53:41,845 - ERROR - systemlog.py - log_error - 47 - 'NoneType' object is not iterable
2019-01-17 10:53:41,847 - ERROR - systemlog.py - log_error - 47 - 'NoneType' object is not iterable
2019-01-17 10:53:41,850 - ERROR - systemlog.py - log_error - 47 - 'NoneType' object is not iterable
2019-01-17 10:53:41,852 - ERROR - systemlog.py - log_error - 47 - 'NoneType' object is not iterable
2019-01-17 10:53:41,853 - ERROR - systemlog.py - log_error - 47 - 'NoneType' object is not iterable
2019-01-17 10:53:41,854 - ERROR - systemlog.py - log_error - 47 - 'NoneType' object is not iterable
2019-02-13 11:54:39,424 - ERROR - systemlog.py - log_error - 47 - (sqlite3.IntegrityError) NOT NULL constraint failed: t_work_record.project_id [SQL: 'UPDATE t_work_record SET project_id=? WHERE t_work_record.id = ?'] [parameters: (None, 4825)] (Background on this error at: http://sqlalche.me/e/gkpj)
2019-02-13 11:56:36,463 - ERROR - systemlog.py - log_error - 47 - (sqlite3.IntegrityError) NOT NULL constraint failed: t_work_record.project_id [SQL: 'UPDATE t_work_record SET project_id=? WHERE t_work_record.id = ?'] [parameters: (None, 4825)] (Background on this error at: http://sqlalche.me/e/gkpj)
2019-02-13 12:05:58,476 - ERROR - systemlog.py - log_error - 47 - (sqlite3.IntegrityError) NOT NULL constraint failed: t_work_record.project_id [SQL: 'UPDATE t_work_record SET project_id=? WHERE t_work_record.id = ?'] [parameters: (None, 4825)] (Background on this error at: http://sqlalche.me/e/gkpj)
2019-02-13 12:20:49,169 - ERROR - systemlog.py - log_error - 47 - object of type 'NoneType' has no len()
2019-02-28 09:16:28,614 - ERROR - systemlog.py - log_error - 47 - (sqlite3.IntegrityError) UNIQUE constraint failed: t_project.id [SQL: 'INSERT INTO t_project (id, name, status, regtime, department_id, super_user_id) VALUES (?, ?, ?, ?, ?, ?)'] [parameters: ('TR190201', 'TR190201 测速雷达', 0, '2019-02-28', '23', '9')] (Background on this error at: http://sqlalche.me/e/gkpj)
2019-02-28 09:19:38,858 - ERROR - systemlog.py - log_error - 47 - object of type 'NoneType' has no len()
2019-02-28 09:24:00,239 - INFO - systemlog.py - log_info - 35 - 未发现数据库...

2019-02-28 09:24:00,239 - INFO - systemlog.py - log_info - 35 - 准备初始化数据库...

2019-02-28 09:24:00,333 - INFO - systemlog.py - log_info - 35 - 数据库初始化完成...
2019-02-28 09:31:23,983 - ERROR - systemlog.py - log_error - 47 - object of type 'NoneType' has no len()
2019-02-28 09:31:34,704 - ERROR - systemlog.py - log_error - 47 - object of type 'NoneType' has no len()
2019-02-28 09:33:40,773 - ERROR - systemlog.py - log_error - 47 - invalid literal for int() with base 10: ''
2019-02-28 10:06:28,768 - ERROR - systemlog.py - log_error - 47 - object of type 'NoneType' has no len()
2019-02-28 10:06:35,635 - ERROR - systemlog.py - log_error - 47 - object of type 'NoneType' has no len()
2019-03-11 09:52:18,293 - ERROR - systemlog.py - log_error - 47 - object of type 'NoneType' has no len()
2019-03-11 10:05:51,269 - ERROR - systemlog.py - log_error - 47 - object of type 'NoneType' has no len()
2019-03-11 10:06:25,592 - ERROR - systemlog.py - log_error - 47 - object of type 'NoneType' has no len()
2019-03-11 10:07:25,787 - INFO - systemlog.py - log_info - 35 - 未发现数据库...

2019-03-11 10:07:25,787 - INFO - systemlog.py - log_info - 35 - 准备初始化数据库...

2019-03-11 10:07:25,873 - INFO - systemlog.py - log_info - 35 - 数据库初始化完成...
2019-03-11 10:08:56,686 - ERROR - systemlog.py - log_error - 47 - object of type 'NoneType' has no len()
2019-03-11 10:09:05,046 - ERROR - systemlog.py - log_error - 47 - object of type 'NoneType' has no len()
2019-03-11 10:09:11,581 - ERROR - systemlog.py - log_error - 47 - object of type 'NoneType' has no len()
2019-03-11 10:10:39,886 - ERROR - systemlog.py - log_error - 47 - object of type 'NoneType' has no len()
2019-03-11 10:10:44,510 - ERROR - systemlog.py - log_error - 47 - object of type 'NoneType' has no len()
2019-03-11 10:10:45,773 - ERROR - systemlog.py - log_error - 47 - object of type 'NoneType' has no len()
2019-03-11 10:10:48,660 - ERROR - systemlog.py - log_error - 47 - object of type 'NoneType' has no len()
2019-03-11 10:10:49,398 - ERROR - systemlog.py - log_error - 47 - object of type 'NoneType' has no len()
2019-03-11 10:10:53,365 - ERROR - systemlog.py - log_error - 47 - (sqlite3.IntegrityError) NOT NULL constraint failed: t_user.department_id [SQL: 'UPDATE t_user SET department_id=? WHERE t_user.id = ?'] [parameters: ((None, 3), (None, 4))] (Background on this error at: http://sqlalche.me/e/gkpj)
2019-03-11 10:11:08,368 - ERROR - systemlog.py - log_error - 47 - (sqlite3.IntegrityError) NOT NULL constraint failed: t_user.department_id [SQL: 'UPDATE t_user SET department_id=? WHERE t_user.id = ?'] [parameters: ((None, 3), (None, 4))] (Background on this error at: http://sqlalche.me/e/gkpj)
2019-03-11 10:11:31,200 - ERROR - systemlog.py - log_error - 47 - object of type 'NoneType' has no len()
2019-03-11 10:11:35,989 - ERROR - systemlog.py - log_error - 47 - object of type 'NoneType' has no len()
2019-03-21 20:24:51,078 - ERROR - systemlog.py - log_error - 47 - object of type 'NoneType' has no len()
